<?xml version="1.0"?>
<robot xmlns:xacro="http://ros.org/wiki/xacro">
<xacro:macro name="left_leg_links">
<!-- LEFT Upper HIP  -->
    <link name='left_leg_upper_hip_link'>
      <origin xyz="0 0 0" rpy="0 -0 0"/>
      <gravity>1</gravity>
      <self_collide>0</self_collide>
      <kinematic>0</kinematic>

      <visual name='left_leg_upper_hip_visual'>
        <origin xyz="0 0 0" rpy="0 -0 0"/>
        <geometry>
          <mesh filename="package://hros1_description/meshes/left_leg_yaw_link.stl"/>
        </geometry>
      </visual>
      
      <inertial>
        <origin xyz="0 0.017 -0.014" rpy="0 -0 0"/>
        <mass value="0.017"/>
        <inertia
          ixx="0.000016"
          ixy="0.0"
          ixz="0.0"
          
          iyy="0.0000035"
          iyz="0.0"
          
          izz="0.000015"
          />
      </inertial>
    </link>  

<!-- LEFT LOWER HIP  -->
    <link name='left_leg_lower_hip_link'>
      <origin xyz="0 0 0 0 -0 0"/>
      <gravity>1</gravity>
      <self_collide>0</self_collide>
      <kinematic>0</kinematic>

      <visual name='left_leg_lower_hip_visual'>
        <origin xyz="0 0 0" rpy="0 -0 0"/>
        <geometry>
          <mesh filename="package://hros1_description/meshes/left_leg_hip_joint.stl"/>
        </geometry>
      </visual>
      
      <inertial>
        <origin xyz="0.0 -0.037 -0.013" rpy="0 -0 0"/>
        <mass value="0.110"/>
        <inertia
          ixx="0.000058"
          ixy="-0.00000051"
          ixz="-0.00000024"
          
          iyy="0.000029"
          iyz="0.00000027"
          
          izz="0.000046"
          />
      </inertial>
    </link> 


<!-- LEFT THIGH  -->
    <link name='left_leg_thigh_link'>
      <origin xyz="0 0 0 0 -0 0"/>
      <gravity>1</gravity>
      <self_collide>0</self_collide>
      <kinematic>0</kinematic>

      <visual name='left_leg_thigh_visual'>
        <origin xyz="0 0 0" rpy="0 -0 0"/>
        <geometry>
          <mesh filename="package://hros1_description/meshes/left_leg_thigh.stl"/>
        </geometry>
      </visual>
      
      <inertial>
        <origin xyz="0.015 -0.011 -0.043" rpy="0 -0 0"/>
        <mass value="0.028"/>
        <inertia
          ixx="0.000016"
          ixy="0.0"
          ixz="0.0"
          
          iyy="0.000023"
          iyz="-0.000002"
          
          izz="0.000013"
          />
      </inertial>
    </link>

<!-- LEFT KNEE  -->
    <link name='left_leg_knee_link'>
      <origin xyz="0 0 0" rpy="0 -0 0"/>
      <gravity>1</gravity>
      <self_collide>0</self_collide>
      <kinematic>0</kinematic>

      <visual name='left_leg_knee_visual'>
        <origin xyz="0 0 0" rpy="0 -0 0"/>
        <geometry>
          <mesh filename="package://hros1_description/meshes/left_leg_knee.stl"/>
        </geometry>
      </visual>
      
      <inertial>
        <origin xyz="0.020 -0.013 -0.004" rpy="0 -0 0"/>
        <mass value="0.055"/>
        <inertia
          ixx="0.000013"
          ixy="-0.00000025"
          ixz="-0.000000074"
          
          iyy="0.0000090"
          iyz="-0.0000019"
          
          izz="0.000015"
          />
      </inertial>
    </link>



<!-- LEFT SHIN  -->
    <link name='left_leg_shin_link'>
      <origin xyz="0 0 0" rpy="0 -0 0"/>
      <gravity>1</gravity>
      <self_collide>0</self_collide>
      <kinematic>0</kinematic>

      <visual name='left_leg_shin_visual'>
        <origin xyz="0 0 0" rpy="0 -0 0"/>
        <geometry>
          <mesh filename="package://hros1_description/meshes/left_leg_shin.stl"/>
        </geometry>
      </visual>
      
      <inertial>
        <origin xyz="0.017 -0.002 -0.023" rpy="0 -0 0"/>
        <mass value="0.021"/>
        <inertia
          ixx="0.0000094"
          ixy="0.0"
          ixz="0.0"
          
          iyy="0.000014"
          iyz="0.0000018"
          
          izz="0.0000088"
          />
      </inertial>
    </link>


<!-- LEFT ANKLE  -->
    <link name='left_leg_ankle_link'>
      <origin xyz="0 0 0" rpy="0 -0 0"/>
      <gravity>1</gravity>
      <self_collide>0</self_collide>
      <kinematic>0</kinematic>

      <visual name='left_leg_ankle_visual'>
        <origin xyz="0 0 0" rpy="0 -0 0"/>
        <geometry>
          <mesh filename="package://hros1_description/meshes/left_leg_ankle_joint.stl"/>
        </geometry>
      </visual>
      
      <inertial>
        <origin xyz="0.020 0.016 0.013" rpy="0 -0 0"/>
        <mass value="0.110"/>
        <inertia
          ixx="0.000058"
          ixy="-0.00000045"
          ixz="0.00000027"
          
          iyy="0.000029"
          iyz="-0.00000024"
          
          izz="0.000046"
          />
      </inertial>
    </link>


<!-- LEFT FOOT  -->
    <link name='left_leg_foot_link'>
      <origin xyz="0 0 0" rpy="0 -0 0"/>
      <gravity>1</gravity>
      <self_collide>0</self_collide>
      <kinematic>0</kinematic>

      <visual name='left_leg_foot_visual'>
        <origin xyz="0 0 0" rpy="0 -0 0"/>
        <geometry>
          <mesh filename="package://hros1_description/meshes/left_leg_foot.stl"/>
        </geometry>
      </visual>
      
      <collision name="collision">
        <origin xyz=" -0.05 -0.05 -0.195" rpy="0 0 0 "/>
        <geometry>
          <box size="0.065 .1 0.01"/>
        </geometry>
      </collision>
      
      <inertial>
        <origin xyz="0.008 -0.046 -0.028" rpy="0 -0 0"/>
        <mass value="0.067"/>
        <inertia
          ixx="0.000006"
          ixy="0.0000017"
          ixz="0.0000011"
          
          iyy="0.000026"
          iyz="-0.0000014"
          
          izz="0.00008"
          />
      </inertial>
    </link>
 -->
</xacro:macro>

<xacro:macro name="left_leg_joints">
  <joint name="left_hip_yaw_powered_joint" type="revolute">
    <parent link="body_structure_link"/>
    <child link="left_leg_upper_hip_link"/>
    <axis xyz="0 0 1"/>
    <origin xyz="0.039 0.045 0.023" rpy="0 0 0"/>
    <xacro:ax12_limits />
  </joint>
  
  
  <joint name="left_hip_roll_powered_joint" type="revolute">
    <parent link="left_leg_upper_hip_link"/>
    <child link="left_leg_lower_hip_link"/>
    <axis xyz="0 1 0"/>
    <origin xyz="0 0.053 -0.036" rpy="0 0 0"/>
    <xacro:ax12_limits />
  </joint>
  
  
  <joint name="left_hip_pitch_powered_joint" type="revolute">
    <parent link="left_leg_lower_hip_link"/>
    <child link="left_leg_thigh_link"/>
    <axis xyz="1 0 0"/>
    <origin xyz="-0.015 -0.053 0" rpy="0 0 0"/>
    <xacro:ax12_limits />
  </joint>
  
  
  <joint name="left_knee_pitch_powered_joint" type="revolute">
    <parent link="left_leg_thigh_link"/>
    <child link="left_leg_knee_link"/>
    <axis xyz="1 0 0"/>
    <origin xyz="-0.006 -0.006 -0.077" rpy="0 0 0"/>
    <xacro:ax12_limits />
  </joint>
  
  <joint name="left_knee-shin_fixed_joint" type="fixed">
    <parent link="left_leg_knee_link"/>
    <child link="left_leg_shin_link"/>
    <axis xyz="0 0 1"/>
    <origin xyz="0.004 -0.002 -0.015" rpy="0 0 0"/>
    <xacro:ax12_limits />
  </joint>
  
  
  <joint name="left_ankle_pitch_powered_joint" type="revolute">
    <parent link="left_leg_shin_link"/>
    <child link="left_leg_ankle_link"/>
    <axis xyz="1 0 0"/>
    <origin xyz="-0.004 0.008 -0.058" rpy="0 0 0"/>
    <xacro:ax12_limits />
  </joint>
  
  <joint name="left_ankle_roll_powered_joint" type="revolute">
    <parent link="left_leg_ankle_link"/>
    <child link="left_leg_foot_link"/>
    <axis xyz="0 1 0"/>
    <origin xyz="0.021 0.053 0" rpy="0 0 0"/>
    <xacro:ax12_limits />
  </joint>
</xacro:macro>
</robot>
