<?xml version="1.0"?>
<robot xmlns:xacro="http://ros.org/wiki/xacro">



<xacro:macro name="neck_links">
    <!--  ATTACHED TO TOP OF BODY -->
    <link name='neck_link_1_link'>
      <origin xyz="0 0 0" rpy="0 -0 0"/>
      <gravity>1</gravity>
      <self_collide>0</self_collide>
      <kinematic>0</kinematic>

      <visual name='neck_link_1_visual'>
        <origin xyz="0 0 0" rpy="0 -0 0"/>
        <geometry>
          <mesh filename="package://hros1_description/meshes/neck_link_1.stl"/>
        </geometry>
      </visual>
      
      <inertial>
        <origin xyz="0 0 0.023" rpy="0 -0 0"/>
        <mass value="0.005"/>
        <inertia
          ixx="0.0000012"
          ixy="0.0"
          ixz="0.0"
          
          iyy="0.0000032"
          iyz="0.0"
          
          izz="0.000002"
          />
      </inertial>
    </link>
  
    <!--  NECK Head (Pitch Servo) -->
<!--  ATTACHED TO BACK OF HEAD  -->
    <link name='neck_head_link'>
      <origin xyz="0 0 0" rpy="0 -0 0"/>
      <gravity>1</gravity>
      <self_collide>1</self_collide>
      <kinematic>0</kinematic>

      <visual name='neck_head_visual'>
        <origin xyz="0 0 0" rpy="0 -0 0"/>
        <geometry>
          <mesh filename="package://hros1_description/meshes/neck_head_servo.stl"/>
        </geometry>
      </visual>
      <collision name="collision">
        <origin xyz=" 0.0 -0.05 0.22" rpy="0 0 0 "/>
        <geometry>
          <box size="0.02 0.02 0.02"/>
        </geometry>
      </collision>
      
      <inertial>
        <origin xyz="0 -0.015 -0.005" rpy="0 -0 0"/>
        <mass value="0.127"/>
        <inertia
          ixx="0.000036"
          ixy="0.00000050"
          ixz="-0.00000017"
          
          iyy="0.000027"
          iyz="-0.00000037"
          
          izz="0.000038"
          />
      </inertial>
    </link>

<!--  NECK Base (YAW SERVO) -->
<!--  ATTACHED TO BACK OF HEAD  -->

    <link name='neck_base_link'>
      <origin xyz="0 0.0 0.0" rpy="0 -0 0"/>
      <gravity>1</gravity>
      <self_collide>0</self_collide>
      <kinematic>0</kinematic>

      <visual name='neck_base_visual'>
        <origin xyz="0 0.0 0" rpy="0 -0 0"/>
        <geometry>
          <mesh filename="package://hros1_description/meshes/neck_base.stl"/>
        </geometry>
      </visual>
      
      <inertial>
        <origin xyz="0 0.017 0.02" rpy="0 -0 0"/>
        <mass value="0.075"/>
        <inertia
          ixx="0.000029"
          ixy="0.000000002"
          ixz="-0.0000000069"
          
          iyy="0.000016"
          iyz="0.00000045"
          
          izz="0.000026"
          />
      </inertial>
    </link>

<!--  Neck Head Platform  -->
<!--  Supports to head; should be able to tilt  -->
    <link name='neck_base_platform_link'>
      <origin xyz="0 0 0" rpy="0 -0 0"/>
      <gravity>1</gravity>
      <self_collide>1</self_collide>
      <kinematic>0</kinematic>

      <visual name='neck_base_platform_visual'>
        <origin xyz="0 0 0" rpy="0 -0 0"/>
        <geometry>
          <mesh filename="package://hros1_description/meshes/neck_base_platform.stl"/>
        </geometry>
      </visual>
      <collision name="collision">
        <origin xyz="0 -0.046 0.20955" rpy="0 0 0"/>
        <geometry>
          <cylinder radius="0.02" length="0.0025"/>
        </geometry>
      </collision>
      
      <inertial>
        <origin xyz="0 0 0.006" rpy="0 -0 0"/>
        <mass value="0.012"/>
        <inertia
          ixx="0.0000017"
          ixy="0.0"
          ixz="0.0"
          
          iyy="0.0000019"
          iyz="0.0"
          
          izz="0.0000034"
          />
      </inertial>
    </link> 


<!--  NECK Link 2  -->
<!--  ATTACHED TO Head Servo  -->
    <link name='neck_link_2_link'>
      <origin xyz="0 0 0" rpy="0 -0 0"/>
      <gravity>1</gravity>
      <self_collide>0</self_collide>
      <kinematic>0</kinematic>

      <visual name='neck_link_2_visual'>
        <origin xyz="0 0 0" rpy="0 -0 0"/>
        <geometry>
          <mesh filename="package://hros1_description/meshes/neck_link_2.stl"/>
        </geometry>
      </visual>
      
      <inertial>
        <origin xyz="0.001 -0.024 0.0" rpy="0 -0 0"/>
        <mass value="0.011"/>
        <inertia
          ixx="0.000002"
          ixy="0.0"
          ixz="0.0"
          
          iyy="0.0000057"
          iyz="0.0"
          
          izz="0.0000071"
          />
      </inertial>
    </link>
    
</xacro:macro>


<xacro:macro name="neck_joints">
  <joint name="neck_yaw_powered_joint" type="revolute">
    <parent link="body_structure_link"/>
    <child link="neck_base_link"/>
    <xacro:ax12_limits />
    <xacro:ax12_dynamics />
    <axis xyz="0 0 1"/>
    <origin xyz="0 0.052 0.16" rpy="0 -0 0"/>
  </joint>


  <joint name="neck_base_platform_free_joint" type="revolute">
    <parent link="neck_base_link"/>
    <child link="neck_base_platform_link"/>
    <limit effort="0" velocity="1" upper="3.1415" lower="-3.1415"/>
    <xacro:loose_dynamics />
    <axis xyz="1 0 0"/>
    <origin xyz="0.0 0.0005 0.0425" rpy="0 -0 0"/>
  </joint>
  

  <joint name="neck_pitch_1_free_joint" type="continuous">
    <parent link="neck_base_link"/>
    <child link="neck_link_1_link"/>
    <limit effort="0" velocity="1" upper="3.1415" lower="-3.1415"/>
    <xacro:loose_dynamics />
    <axis xyz="1 0 0"/>
    <origin xyz="0 0.05 0.026" rpy="0 -0 0"/>
  </joint>
  
  <joint name="neck_pitch_2_free_joint" type="continuous">
    <parent link="neck_link_1_link"/>
    <child link="neck_link_2_link"/>
    <limit effort="0" velocity="1" upper="3.1415" lower="-3.1415"/>
    <xacro:loose_dynamics />
    <axis xyz="1 0 0"/>
    <origin xyz="0 0 0.046" rpy="0 -0 0"/>
  </joint>
  
 
  <joint name="neck_pitch_main_powered_joint" type="revolute">
    <parent link="neck_link_2_link"/>
    <child link="neck_head_link"/>
    <xacro:ax12_limits />
    <xacro:ax12_dynamics />
    <axis xyz="-1 0 0"/>
    <origin xyz="0 -0.034 0.0" rpy="0 -0 0"/>
  </joint>
</xacro:macro>
</robot>
