<?xml version="1.0"?>
<robot xmlns:xacro="http://ros.org/wiki/xacro">
<xacro:macro name="left_leg_links">
<!-- LEFT Upper HIP  -->
    <link name='HR-OS1::left_leg_upper_hip_link'>
      <pose>0 0 0 0 -0 0</pose>
      <gravity>1</gravity>
      <self_collide>0</self_collide>
      <kinematic>0</kinematic>

      <visual name='left_leg_upper_hip_visual'>
        <pose>0 0 0 0 -0 0</pose>
        <geometry>
          <mesh>
            <uri>model://HR-OS1/meshes/HROS1_Simple - Left_Leg_Yaw_Link.stl</uri>
            <scale>1 1 1</scale>
          </mesh>
        </geometry>
        <material>
          <script>
            <uri>file://media/materials/scripts/gazebo.material</uri>
            <name>Gazebo/Grey</name>
          </script>
        </material>
      </visual>
      
      <inertial>
        <pose>0.039 -0.062 0.011 0 -0 0</pose>
        <mass>0.017</mass>
        <inertia>
          <ixx>0.000016</ixx>
          <ixy>0.0</ixy>
          <ixz>0.0</ixz>
          
          <iyy>0.0000035</iyy>
          <iyz>0.0</iyz>
          
          <izz>0.000015</izz>
          </inertia>
      </inertial>
    </link>  

<!-- LEFT LOWER HIP  -->
    <link name='HR-OS1::left_leg_lower_hip_link'>
      <pose>0 0 0 0 -0 0</pose>
      <gravity>1</gravity>
      <self_collide>0</self_collide>
      <kinematic>0</kinematic>

      <visual name='left_leg_lower_hip_visual'>
        <pose>0 0 0 0 -0 0</pose>
        <geometry>
          <mesh>
            <uri>model://HR-OS1/meshes/HROS1_Simple - Left_Leg_Hip_Joint.stl</uri>
            <scale>1 1 1</scale>
          </mesh>
        </geometry>
        <material>
          <script>
            <uri>file://media/materials/scripts/gazebo.material</uri>
            <name>Gazebo/Grey</name>
          </script>
        </material>
      </visual>
      
      <inertial>
        <pose>0.039 -0.062 -0.024 0 -0 0</pose>
        <mass>0.110</mass>
        <inertia>
          <ixx>0.000058</ixx>
          <ixy>-0.00000051</ixy>
          <ixz>-0.00000024</ixz>
          
          <iyy>0.000029</iyy>
          <iyz>0.00000027</iyz>
          
          <izz>0.000046</izz>
          </inertia>
      </inertial>
    </link> 


<!-- LEFT THIGH  -->
    <link name='HR-OS1::left_leg_thigh_link'>
      <pose>0 0 0 0 -0 0</pose>
      <gravity>1</gravity>
      <self_collide>0</self_collide>
      <kinematic>0</kinematic>

      <visual name='left_leg_thigh_visual'>
        <pose>0 0 0 0 -0 0</pose>
        <geometry>
          <mesh>
            <uri>model://HR-OS1/meshes/HROS1_Simple - Left_Leg_Thigh.stl</uri>
            <scale>1 1 1</scale>
          </mesh>
        </geometry>
        <material>
          <script>
            <uri>file://media/materials/scripts/gazebo.material</uri>
            <name>Gazebo/Grey</name>
          </script>
        </material>
      </visual>
      
      <inertial>
        <pose>0.039 -0.034 -0.053 0 -0 0</pose>
        <mass>0.028</mass>
        <inertia>
          <ixx>0.000016</ixx>
          <ixy>0.0</ixy>
          <ixz>0.0</ixz>
          
          <iyy>0.000023</iyy>
          <iyz>-0.000002</iyz>
          
          <izz>0.000013</izz>
          </inertia>
      </inertial>
    </link>

<!-- LEFT KNEE  -->
    <link name='HR-OS1::left_leg_knee_link'>
      <pose>0 0 0 0 -0 0</pose>
      <gravity>1</gravity>
      <self_collide>0</self_collide>
      <kinematic>0</kinematic>

      <visual name='left_leg_knee_visual'>
        <pose>0 0 0 0 -0 0</pose>
        <geometry>
          <mesh>
            <uri>model://HR-OS1/meshes/HROS1_Simple - Left_Leg_Knee.stl</uri>
            <scale>1 1 1</scale>
          </mesh>
        </geometry>
        <material>
          <script>
            <uri>file://media/materials/scripts/gazebo.material</uri>
            <name>Gazebo/Grey</name>
          </script>
        </material>
      </visual>
      
      <inertial>
        <pose>0.038 -0.027 -0.091 0 -0 0</pose>
        <mass>0.055</mass>
        <inertia>
          <ixx>0.000013</ixx>
          <ixy>-0.00000025</ixy>
          <ixz>-0.000000074</ixz>
          
          <iyy>0.0000090</iyy>
          <iyz>-0.0000019</iyz>
          
          <izz>0.000015</izz>
          </inertia>
      </inertial>
    </link>



<!-- LEFT SHIN  -->
    <link name='HR-OS1::left_leg_shin_link'>
      <pose>0 0 0 0 -0 0</pose>
      <gravity>1</gravity>
      <self_collide>0</self_collide>
      <kinematic>0</kinematic>

      <visual name='left_leg_shin_visual'>
        <pose>0 0 0 0 -0 0</pose>
        <geometry>
          <mesh>
            <uri>model://HR-OS1/meshes/HROS1_Simple - Left_Leg_Shin.stl</uri>
            <scale>1 1 1</scale>
          </mesh>
        </geometry>
        <material>
          <script>
            <uri>file://media/materials/scripts/gazebo.material</uri>
            <name>Gazebo/Grey</name>
          </script>
        </material>
      </visual>
      
      <inertial>
        <pose>0.039 -0.035 -0.125 0 -0 0</pose>
        <mass>0.021</mass>
        <inertia>
          <ixx>0.0000094</ixx>
          <ixy>0.0</ixy>
          <ixz>0.0</ixz>
          
          <iyy>0.000014</iyy>
          <iyz>0.0000018</iyz>
          
          <izz>0.0000088</izz>
          </inertia>
      </inertial>
    </link>

<!-- LEFT ANKLE  -->
    <link name='HR-OS1::left_leg_ankle_link'>
      <pose>0 0 0 0 -0 0</pose>
      <gravity>1</gravity>
      <self_collide>0</self_collide>
      <kinematic>0</kinematic>

      <visual name='left_leg_ankle_visual'>
        <pose>0 0 0 0 -0 0</pose>
        <geometry>
          <mesh>
            <uri>model://HR-OS1/meshes/HROS1_Simple - Left_Leg_Ankle_Joint.stl</uri>
            <scale>1 1 1</scale>
          </mesh>
        </geometry>
        <material>
          <script>
            <uri>file://media/materials/scripts/gazebo.material</uri>
            <name>Gazebo/Grey</name>
          </script>
        </material>
      </visual>
      
      <inertial>
        <pose>0.039 -0.062 -0.147 0 -0 0</pose>
        <mass>0.110</mass>
        <inertia>
          <ixx>0.000058</ixx>
          <ixy>-0.00000045</ixy>
          <ixz>0.00000027</ixz>
          
          <iyy>0.000029</iyy>
          <iyz>-0.00000024</iyz>
          
          <izz>0.000046</izz>
          </inertia>
      </inertial>
    </link>

<!-- LEFT FOOT  -->
    <link name='HR-OS1::left_leg_foot_link'>
      <pose>0 0 0 0 -0 0</pose>
      <gravity>1</gravity>
      <self_collide>0</self_collide>
      <kinematic>0</kinematic>

      <visual name='left_leg_foot_visual'>
        <pose>0 0 0 0 -0 0</pose>
        <geometry>
          <mesh>
            <uri>model://HR-OS1/meshes/HROS1_Simple - Left_Leg_Foot.stl</uri>
            <scale>1 1 1</scale>
          </mesh>
        </geometry>
        <material>
          <script>
            <uri>file://media/materials/scripts/gazebo.material</uri>
            <name>Gazebo/Grey</name>
          </script>
        </material>
      </visual>
      
      <collision name="collision">
        <pose> -0.05 -0.05 -0.195 0 0 0 </pose>
        <geometry>
          <box>
            <size>0.065 .1 0.01</size>
          </box>
        </geometry>
      </collision>
      
      <inertial>
        <pose>0.046 -0.052 -0.188 0 -0 0</pose>
        <mass>0.067</mass>
        <inertia>
          <ixx>0.000006</ixx>
          <ixy>0.0000017</ixy>
          <ixz>0.0000011</ixz>
          
          <iyy>0.000026</iyy>
          <iyz>-0.0000014</iyz>
          
          <izz>0.00008</izz>
          </inertia>
      </inertial>
    </link>
</xacro:macro>

<xacro:macro name="left_leg_joints">
  <joint name="left_hip_yaw_powered_joint" type="revolute">
    <parent>HR-OS1::body_structure_link</parent>
    <child>HR-OS1::left_leg_upper_hip_link</child>
    <axis>
      <xyz>0 0 -1</xyz>
    </axis>
    <pose>-0.040 -0.045 0 0 0 0</pose>
  </joint>
  
  
  <joint name="left_hip_roll_powered_joint" type="revolute">
    <parent>HR-OS1::left_leg_upper_hip_link</parent>
    <child>HR-OS1::left_leg_lower_hip_link</child>
    <axis>
      <xyz>0 1 0</xyz>
    </axis>
    <pose>-0.040 -0.045 -0.01 0 0 0</pose>
  </joint>
  
  
  <joint name="left_hip_pitch_powered_joint" type="revolute">
    <parent>HR-OS1::left_leg_lower_hip_link</parent>
    <child>HR-OS1::left_leg_thigh_link</child>
    <axis>
      <xyz>1 0 0</xyz>
    </axis>
    <pose>-0.040 -0.045 -0.01 0 0 0</pose>
  </joint>
  
  
  <joint name="left_knee_pitch_powered_joint" type="revolute">
    <parent>HR-OS1::left_leg_thigh_link</parent>
    <child>HR-OS1::left_leg_knee_link</child>
    <axis>
      <xyz>-1 0 0</xyz>
    </axis>
    <pose>-0.015 -0.04 -0.09 0 0 0</pose>
  </joint>
  
  
  <joint name="left_knee-shin_fixed_joint" type="revolute">
    <parent>HR-OS1::left_leg_knee_link</parent>
    <child>HR-OS1::left_leg_shin_link</child>
    <axis>
      <xyz>1 0 0</xyz>
      <limit>
          <lower>0</lower>
          <upper>0</upper>
      </limit>
    </axis>
    <pose>-0.015 -0.04 -0.09 0 0 0</pose>
  </joint>
  
  
  <joint name="left_ankle_pitch_powered_joint" type="revolute">
    <parent>HR-OS1::left_leg_shin_link</parent>
    <child>HR-OS1::left_leg_ankle_link</child>
    <axis>
      <xyz>-1 0 0</xyz>
    </axis>
    <pose>-0.015 -0.045 -0.16 0 0 0</pose>
  </joint>
  
  
  <joint name="left_ankle_roll_powered_joint" type="revolute">
    <parent>HR-OS1::left_leg_ankle_link</parent>
    <child>HR-OS1::left_leg_foot_link</child>
    <axis>
      <xyz>0 -1 0</xyz>
    </axis>
    <pose>-0.04 -0.045 -0.16 0 0 0</pose>
  </joint>
</xacro:macro>
</robot>